2017-04-16 19:04:37,993: radical.saga.pty    : umgr.scheduling.1               : MainThread     : ERROR   : read from process failed '[Errno 5] Input/output error' : (Permission denied (gssapi-keyex,gssapi-with-mic).
) ((Permission denied (gssapi-keyex,gssapi-with-mic).
)) (/home/mingtha/ve/ve.exec_model_exp/local/lib/python2.7/site-packages/saga/utils/pty_exceptions.py +61 (translate_exception)  :  e = se.PermissionDenied (cmsg))
Traceback (most recent call last):
  File "/home/mingtha/ve/ve.exec_model_exp/local/lib/python2.7/site-packages/saga/utils/pty_shell_factory.py", line 307, in _initialize_pty
    n, match = pty_shell.find (prompt_patterns, delay)
  File "/home/mingtha/ve/ve.exec_model_exp/local/lib/python2.7/site-packages/saga/utils/pty_process.py", line 790, in find
    raise ptye.translate_exception (e, "(%s)" % data)
PermissionDenied: read from process failed '[Errno 5] Input/output error' : (Permission denied (gssapi-keyex,gssapi-with-mic).
) ((Permission denied (gssapi-keyex,gssapi-with-mic).
)) (/home/mingtha/ve/ve.exec_model_exp/local/lib/python2.7/site-packages/saga/utils/pty_exceptions.py +61 (translate_exception)  :  e = se.PermissionDenied (cmsg))
2017-04-16 19:04:39,310: radical.saga.pty    : umgr.scheduling.1               : MainThread     : ERROR   : read from process failed '[Errno 5] Input/output error' : (Permission denied (gssapi-keyex,gssapi-with-mic).
) ((Permission denied (gssapi-keyex,gssapi-with-mic).
)) (/home/mingtha/ve/ve.exec_model_exp/local/lib/python2.7/site-packages/saga/utils/pty_exceptions.py +61 (translate_exception)  :  e = se.PermissionDenied (cmsg))
Traceback (most recent call last):
  File "/home/mingtha/ve/ve.exec_model_exp/local/lib/python2.7/site-packages/saga/utils/pty_shell_factory.py", line 307, in _initialize_pty
    n, match = pty_shell.find (prompt_patterns, delay)
  File "/home/mingtha/ve/ve.exec_model_exp/local/lib/python2.7/site-packages/saga/utils/pty_process.py", line 790, in find
    raise ptye.translate_exception (e, "(%s)" % data)
PermissionDenied: read from process failed '[Errno 5] Input/output error' : (Permission denied (gssapi-keyex,gssapi-with-mic).
) ((Permission denied (gssapi-keyex,gssapi-with-mic).
)) (/home/mingtha/ve/ve.exec_model_exp/local/lib/python2.7/site-packages/saga/utils/pty_exceptions.py +61 (translate_exception)  :  e = se.PermissionDenied (cmsg))
2017-04-16 19:04:40,454: radical.saga.pty    : umgr.scheduling.1               : MainThread     : ERROR   : read from process failed '[Errno 5] Input/output error' : (Permission denied (gssapi-keyex,gssapi-with-mic).
) ((Permission denied (gssapi-keyex,gssapi-with-mic).
)) (/home/mingtha/ve/ve.exec_model_exp/local/lib/python2.7/site-packages/saga/utils/pty_exceptions.py +61 (translate_exception)  :  e = se.PermissionDenied (cmsg))
Traceback (most recent call last):
  File "/home/mingtha/ve/ve.exec_model_exp/local/lib/python2.7/site-packages/saga/utils/pty_shell_factory.py", line 307, in _initialize_pty
    n, match = pty_shell.find (prompt_patterns, delay)
  File "/home/mingtha/ve/ve.exec_model_exp/local/lib/python2.7/site-packages/saga/utils/pty_process.py", line 790, in find
    raise ptye.translate_exception (e, "(%s)" % data)
PermissionDenied: read from process failed '[Errno 5] Input/output error' : (Permission denied (gssapi-keyex,gssapi-with-mic).
) ((Permission denied (gssapi-keyex,gssapi-with-mic).
)) (/home/mingtha/ve/ve.exec_model_exp/local/lib/python2.7/site-packages/saga/utils/pty_exceptions.py +61 (translate_exception)  :  e = se.PermissionDenied (cmsg))
2017-04-16 19:04:41,592: radical.saga.pty    : umgr.scheduling.1               : MainThread     : ERROR   : read from process failed '[Errno 5] Input/output error' : (Permission denied (gssapi-keyex,gssapi-with-mic).
) ((Permission denied (gssapi-keyex,gssapi-with-mic).
)) (/home/mingtha/ve/ve.exec_model_exp/local/lib/python2.7/site-packages/saga/utils/pty_exceptions.py +61 (translate_exception)  :  e = se.PermissionDenied (cmsg))
Traceback (most recent call last):
  File "/home/mingtha/ve/ve.exec_model_exp/local/lib/python2.7/site-packages/saga/utils/pty_shell_factory.py", line 307, in _initialize_pty
    n, match = pty_shell.find (prompt_patterns, delay)
  File "/home/mingtha/ve/ve.exec_model_exp/local/lib/python2.7/site-packages/saga/utils/pty_process.py", line 790, in find
    raise ptye.translate_exception (e, "(%s)" % data)
PermissionDenied: read from process failed '[Errno 5] Input/output error' : (Permission denied (gssapi-keyex,gssapi-with-mic).
) ((Permission denied (gssapi-keyex,gssapi-with-mic).
)) (/home/mingtha/ve/ve.exec_model_exp/local/lib/python2.7/site-packages/saga/utils/pty_exceptions.py +61 (translate_exception)  :  e = se.PermissionDenied (cmsg))
2017-04-16 19:04:42,731: radical.saga.pty    : umgr.scheduling.1               : MainThread     : ERROR   : read from process failed '[Errno 5] Input/output error' : (Permission denied (gssapi-keyex,gssapi-with-mic).
) ((Permission denied (gssapi-keyex,gssapi-with-mic).
)) (/home/mingtha/ve/ve.exec_model_exp/local/lib/python2.7/site-packages/saga/utils/pty_exceptions.py +61 (translate_exception)  :  e = se.PermissionDenied (cmsg))
Traceback (most recent call last):
  File "/home/mingtha/ve/ve.exec_model_exp/local/lib/python2.7/site-packages/saga/utils/pty_shell_factory.py", line 307, in _initialize_pty
    n, match = pty_shell.find (prompt_patterns, delay)
  File "/home/mingtha/ve/ve.exec_model_exp/local/lib/python2.7/site-packages/saga/utils/pty_process.py", line 790, in find
    raise ptye.translate_exception (e, "(%s)" % data)
PermissionDenied: read from process failed '[Errno 5] Input/output error' : (Permission denied (gssapi-keyex,gssapi-with-mic).
) ((Permission denied (gssapi-keyex,gssapi-with-mic).
)) (/home/mingtha/ve/ve.exec_model_exp/local/lib/python2.7/site-packages/saga/utils/pty_exceptions.py +61 (translate_exception)  :  e = se.PermissionDenied (cmsg))
2017-04-16 19:04:43,851: radical.saga.pty    : umgr.scheduling.1               : MainThread     : ERROR   : read from process failed '[Errno 5] Input/output error' : (Permission denied (gssapi-keyex,gssapi-with-mic).
) ((Permission denied (gssapi-keyex,gssapi-with-mic).
)) (/home/mingtha/ve/ve.exec_model_exp/local/lib/python2.7/site-packages/saga/utils/pty_exceptions.py +61 (translate_exception)  :  e = se.PermissionDenied (cmsg))
Traceback (most recent call last):
  File "/home/mingtha/ve/ve.exec_model_exp/local/lib/python2.7/site-packages/saga/utils/pty_shell_factory.py", line 307, in _initialize_pty
    n, match = pty_shell.find (prompt_patterns, delay)
  File "/home/mingtha/ve/ve.exec_model_exp/local/lib/python2.7/site-packages/saga/utils/pty_process.py", line 790, in find
    raise ptye.translate_exception (e, "(%s)" % data)
PermissionDenied: read from process failed '[Errno 5] Input/output error' : (Permission denied (gssapi-keyex,gssapi-with-mic).
) ((Permission denied (gssapi-keyex,gssapi-with-mic).
)) (/home/mingtha/ve/ve.exec_model_exp/local/lib/python2.7/site-packages/saga/utils/pty_exceptions.py +61 (translate_exception)  :  e = se.PermissionDenied (cmsg))
2017-04-16 19:04:44,990: radical.saga.pty    : umgr.scheduling.1               : MainThread     : ERROR   : read from process failed '[Errno 5] Input/output error' : (Permission denied (gssapi-keyex,gssapi-with-mic).
) ((Permission denied (gssapi-keyex,gssapi-with-mic).
)) (/home/mingtha/ve/ve.exec_model_exp/local/lib/python2.7/site-packages/saga/utils/pty_exceptions.py +61 (translate_exception)  :  e = se.PermissionDenied (cmsg))
Traceback (most recent call last):
  File "/home/mingtha/ve/ve.exec_model_exp/local/lib/python2.7/site-packages/saga/utils/pty_shell_factory.py", line 307, in _initialize_pty
    n, match = pty_shell.find (prompt_patterns, delay)
  File "/home/mingtha/ve/ve.exec_model_exp/local/lib/python2.7/site-packages/saga/utils/pty_process.py", line 790, in find
    raise ptye.translate_exception (e, "(%s)" % data)
PermissionDenied: read from process failed '[Errno 5] Input/output error' : (Permission denied (gssapi-keyex,gssapi-with-mic).
) ((Permission denied (gssapi-keyex,gssapi-with-mic).
)) (/home/mingtha/ve/ve.exec_model_exp/local/lib/python2.7/site-packages/saga/utils/pty_exceptions.py +61 (translate_exception)  :  e = se.PermissionDenied (cmsg))
2017-04-16 19:04:46,304: radical.saga.pty    : umgr.scheduling.1               : MainThread     : ERROR   : read from process failed '[Errno 5] Input/output error' : (Permission denied (gssapi-keyex,gssapi-with-mic).
) ((Permission denied (gssapi-keyex,gssapi-with-mic).
)) (/home/mingtha/ve/ve.exec_model_exp/local/lib/python2.7/site-packages/saga/utils/pty_exceptions.py +61 (translate_exception)  :  e = se.PermissionDenied (cmsg))
Traceback (most recent call last):
  File "/home/mingtha/ve/ve.exec_model_exp/local/lib/python2.7/site-packages/saga/utils/pty_shell_factory.py", line 307, in _initialize_pty
    n, match = pty_shell.find (prompt_patterns, delay)
  File "/home/mingtha/ve/ve.exec_model_exp/local/lib/python2.7/site-packages/saga/utils/pty_process.py", line 790, in find
    raise ptye.translate_exception (e, "(%s)" % data)
PermissionDenied: read from process failed '[Errno 5] Input/output error' : (Permission denied (gssapi-keyex,gssapi-with-mic).
) ((Permission denied (gssapi-keyex,gssapi-with-mic).
)) (/home/mingtha/ve/ve.exec_model_exp/local/lib/python2.7/site-packages/saga/utils/pty_exceptions.py +61 (translate_exception)  :  e = se.PermissionDenied (cmsg))
