2017-04-16 19:04:37,994: umgr.scheduling.1.child: umgr.scheduling.1               : MainThread     : ERROR   : unit schedule preparation failed
Traceback (most recent call last):
  File "/home/mingtha/ve/ve.exec_model_exp/local/lib/python2.7/site-packages/radical/pilot/umgr/scheduler/round_robin.py", line 131, in _schedule_units
    unit['sandbox'] = self._session._get_unit_sandbox(unit, pilot)
  File "/home/mingtha/ve/ve.exec_model_exp/local/lib/python2.7/site-packages/radical/pilot/session.py", line 846, in _get_unit_sandbox
    pilot_sandbox = self._get_pilot_sandbox(pilot)
  File "/home/mingtha/ve/ve.exec_model_exp/local/lib/python2.7/site-packages/radical/pilot/session.py", line 831, in _get_pilot_sandbox
    session_sandbox = self._get_session_sandbox(pilot)
  File "/home/mingtha/ve/ve.exec_model_exp/local/lib/python2.7/site-packages/radical/pilot/session.py", line 809, in _get_session_sandbox
    global_sandbox  = self._get_global_sandbox(pilot)
  File "/home/mingtha/ve/ve.exec_model_exp/local/lib/python2.7/site-packages/radical/pilot/session.py", line 774, in _get_global_sandbox
    shell = rsup.PTYShell(js_url, self)
  File "/home/mingtha/ve/ve.exec_model_exp/local/lib/python2.7/site-packages/saga/utils/pty_shell.py", line 247, in __init__
    interactive=self.interactive)
  File "/home/mingtha/ve/ve.exec_model_exp/local/lib/python2.7/site-packages/saga/utils/pty_shell_factory.py", line 198, in initialize
    self._initialize_pty (info['pty'], info)
  File "/home/mingtha/ve/ve.exec_model_exp/local/lib/python2.7/site-packages/saga/utils/pty_shell_factory.py", line 413, in _initialize_pty
    raise ptye.translate_exception (e)
PermissionDenied: read from process failed '[Errno 5] Input/output error' : (Permission denied (gssapi-keyex,gssapi-with-mic).
) ((Permission denied (gssapi-keyex,gssapi-with-mic).
)) (/home/mingtha/ve/ve.exec_model_exp/local/lib/python2.7/site-packages/saga/utils/pty_exceptions.py +61 (translate_exception)  :  e = se.PermissionDenied (cmsg))
2017-04-16 19:04:39,312: umgr.scheduling.1.child: umgr.scheduling.1               : MainThread     : ERROR   : unit schedule preparation failed
Traceback (most recent call last):
  File "/home/mingtha/ve/ve.exec_model_exp/local/lib/python2.7/site-packages/radical/pilot/umgr/scheduler/round_robin.py", line 131, in _schedule_units
    unit['sandbox'] = self._session._get_unit_sandbox(unit, pilot)
  File "/home/mingtha/ve/ve.exec_model_exp/local/lib/python2.7/site-packages/radical/pilot/session.py", line 846, in _get_unit_sandbox
    pilot_sandbox = self._get_pilot_sandbox(pilot)
  File "/home/mingtha/ve/ve.exec_model_exp/local/lib/python2.7/site-packages/radical/pilot/session.py", line 831, in _get_pilot_sandbox
    session_sandbox = self._get_session_sandbox(pilot)
  File "/home/mingtha/ve/ve.exec_model_exp/local/lib/python2.7/site-packages/radical/pilot/session.py", line 809, in _get_session_sandbox
    global_sandbox  = self._get_global_sandbox(pilot)
  File "/home/mingtha/ve/ve.exec_model_exp/local/lib/python2.7/site-packages/radical/pilot/session.py", line 774, in _get_global_sandbox
    shell = rsup.PTYShell(js_url, self)
  File "/home/mingtha/ve/ve.exec_model_exp/local/lib/python2.7/site-packages/saga/utils/pty_shell.py", line 247, in __init__
    interactive=self.interactive)
  File "/home/mingtha/ve/ve.exec_model_exp/local/lib/python2.7/site-packages/saga/utils/pty_shell_factory.py", line 198, in initialize
    self._initialize_pty (info['pty'], info)
  File "/home/mingtha/ve/ve.exec_model_exp/local/lib/python2.7/site-packages/saga/utils/pty_shell_factory.py", line 413, in _initialize_pty
    raise ptye.translate_exception (e)
PermissionDenied: read from process failed '[Errno 5] Input/output error' : (Permission denied (gssapi-keyex,gssapi-with-mic).
) ((Permission denied (gssapi-keyex,gssapi-with-mic).
)) (/home/mingtha/ve/ve.exec_model_exp/local/lib/python2.7/site-packages/saga/utils/pty_exceptions.py +61 (translate_exception)  :  e = se.PermissionDenied (cmsg))
2017-04-16 19:04:40,456: umgr.scheduling.1.child: umgr.scheduling.1               : MainThread     : ERROR   : unit schedule preparation failed
Traceback (most recent call last):
  File "/home/mingtha/ve/ve.exec_model_exp/local/lib/python2.7/site-packages/radical/pilot/umgr/scheduler/round_robin.py", line 131, in _schedule_units
    unit['sandbox'] = self._session._get_unit_sandbox(unit, pilot)
  File "/home/mingtha/ve/ve.exec_model_exp/local/lib/python2.7/site-packages/radical/pilot/session.py", line 846, in _get_unit_sandbox
    pilot_sandbox = self._get_pilot_sandbox(pilot)
  File "/home/mingtha/ve/ve.exec_model_exp/local/lib/python2.7/site-packages/radical/pilot/session.py", line 831, in _get_pilot_sandbox
    session_sandbox = self._get_session_sandbox(pilot)
  File "/home/mingtha/ve/ve.exec_model_exp/local/lib/python2.7/site-packages/radical/pilot/session.py", line 809, in _get_session_sandbox
    global_sandbox  = self._get_global_sandbox(pilot)
  File "/home/mingtha/ve/ve.exec_model_exp/local/lib/python2.7/site-packages/radical/pilot/session.py", line 774, in _get_global_sandbox
    shell = rsup.PTYShell(js_url, self)
  File "/home/mingtha/ve/ve.exec_model_exp/local/lib/python2.7/site-packages/saga/utils/pty_shell.py", line 247, in __init__
    interactive=self.interactive)
  File "/home/mingtha/ve/ve.exec_model_exp/local/lib/python2.7/site-packages/saga/utils/pty_shell_factory.py", line 198, in initialize
    self._initialize_pty (info['pty'], info)
  File "/home/mingtha/ve/ve.exec_model_exp/local/lib/python2.7/site-packages/saga/utils/pty_shell_factory.py", line 413, in _initialize_pty
    raise ptye.translate_exception (e)
PermissionDenied: read from process failed '[Errno 5] Input/output error' : (Permission denied (gssapi-keyex,gssapi-with-mic).
) ((Permission denied (gssapi-keyex,gssapi-with-mic).
)) (/home/mingtha/ve/ve.exec_model_exp/local/lib/python2.7/site-packages/saga/utils/pty_exceptions.py +61 (translate_exception)  :  e = se.PermissionDenied (cmsg))
2017-04-16 19:04:41,594: umgr.scheduling.1.child: umgr.scheduling.1               : MainThread     : ERROR   : unit schedule preparation failed
Traceback (most recent call last):
  File "/home/mingtha/ve/ve.exec_model_exp/local/lib/python2.7/site-packages/radical/pilot/umgr/scheduler/round_robin.py", line 131, in _schedule_units
    unit['sandbox'] = self._session._get_unit_sandbox(unit, pilot)
  File "/home/mingtha/ve/ve.exec_model_exp/local/lib/python2.7/site-packages/radical/pilot/session.py", line 846, in _get_unit_sandbox
    pilot_sandbox = self._get_pilot_sandbox(pilot)
  File "/home/mingtha/ve/ve.exec_model_exp/local/lib/python2.7/site-packages/radical/pilot/session.py", line 831, in _get_pilot_sandbox
    session_sandbox = self._get_session_sandbox(pilot)
  File "/home/mingtha/ve/ve.exec_model_exp/local/lib/python2.7/site-packages/radical/pilot/session.py", line 809, in _get_session_sandbox
    global_sandbox  = self._get_global_sandbox(pilot)
  File "/home/mingtha/ve/ve.exec_model_exp/local/lib/python2.7/site-packages/radical/pilot/session.py", line 774, in _get_global_sandbox
    shell = rsup.PTYShell(js_url, self)
  File "/home/mingtha/ve/ve.exec_model_exp/local/lib/python2.7/site-packages/saga/utils/pty_shell.py", line 247, in __init__
    interactive=self.interactive)
  File "/home/mingtha/ve/ve.exec_model_exp/local/lib/python2.7/site-packages/saga/utils/pty_shell_factory.py", line 198, in initialize
    self._initialize_pty (info['pty'], info)
  File "/home/mingtha/ve/ve.exec_model_exp/local/lib/python2.7/site-packages/saga/utils/pty_shell_factory.py", line 413, in _initialize_pty
    raise ptye.translate_exception (e)
PermissionDenied: read from process failed '[Errno 5] Input/output error' : (Permission denied (gssapi-keyex,gssapi-with-mic).
) ((Permission denied (gssapi-keyex,gssapi-with-mic).
)) (/home/mingtha/ve/ve.exec_model_exp/local/lib/python2.7/site-packages/saga/utils/pty_exceptions.py +61 (translate_exception)  :  e = se.PermissionDenied (cmsg))
2017-04-16 19:04:42,732: umgr.scheduling.1.child: umgr.scheduling.1               : MainThread     : ERROR   : unit schedule preparation failed
Traceback (most recent call last):
  File "/home/mingtha/ve/ve.exec_model_exp/local/lib/python2.7/site-packages/radical/pilot/umgr/scheduler/round_robin.py", line 131, in _schedule_units
    unit['sandbox'] = self._session._get_unit_sandbox(unit, pilot)
  File "/home/mingtha/ve/ve.exec_model_exp/local/lib/python2.7/site-packages/radical/pilot/session.py", line 846, in _get_unit_sandbox
    pilot_sandbox = self._get_pilot_sandbox(pilot)
  File "/home/mingtha/ve/ve.exec_model_exp/local/lib/python2.7/site-packages/radical/pilot/session.py", line 831, in _get_pilot_sandbox
    session_sandbox = self._get_session_sandbox(pilot)
  File "/home/mingtha/ve/ve.exec_model_exp/local/lib/python2.7/site-packages/radical/pilot/session.py", line 809, in _get_session_sandbox
    global_sandbox  = self._get_global_sandbox(pilot)
  File "/home/mingtha/ve/ve.exec_model_exp/local/lib/python2.7/site-packages/radical/pilot/session.py", line 774, in _get_global_sandbox
    shell = rsup.PTYShell(js_url, self)
  File "/home/mingtha/ve/ve.exec_model_exp/local/lib/python2.7/site-packages/saga/utils/pty_shell.py", line 247, in __init__
    interactive=self.interactive)
  File "/home/mingtha/ve/ve.exec_model_exp/local/lib/python2.7/site-packages/saga/utils/pty_shell_factory.py", line 198, in initialize
    self._initialize_pty (info['pty'], info)
  File "/home/mingtha/ve/ve.exec_model_exp/local/lib/python2.7/site-packages/saga/utils/pty_shell_factory.py", line 413, in _initialize_pty
    raise ptye.translate_exception (e)
PermissionDenied: read from process failed '[Errno 5] Input/output error' : (Permission denied (gssapi-keyex,gssapi-with-mic).
) ((Permission denied (gssapi-keyex,gssapi-with-mic).
)) (/home/mingtha/ve/ve.exec_model_exp/local/lib/python2.7/site-packages/saga/utils/pty_exceptions.py +61 (translate_exception)  :  e = se.PermissionDenied (cmsg))
2017-04-16 19:04:43,853: umgr.scheduling.1.child: umgr.scheduling.1               : MainThread     : ERROR   : unit schedule preparation failed
Traceback (most recent call last):
  File "/home/mingtha/ve/ve.exec_model_exp/local/lib/python2.7/site-packages/radical/pilot/umgr/scheduler/round_robin.py", line 131, in _schedule_units
    unit['sandbox'] = self._session._get_unit_sandbox(unit, pilot)
  File "/home/mingtha/ve/ve.exec_model_exp/local/lib/python2.7/site-packages/radical/pilot/session.py", line 846, in _get_unit_sandbox
    pilot_sandbox = self._get_pilot_sandbox(pilot)
  File "/home/mingtha/ve/ve.exec_model_exp/local/lib/python2.7/site-packages/radical/pilot/session.py", line 831, in _get_pilot_sandbox
    session_sandbox = self._get_session_sandbox(pilot)
  File "/home/mingtha/ve/ve.exec_model_exp/local/lib/python2.7/site-packages/radical/pilot/session.py", line 809, in _get_session_sandbox
    global_sandbox  = self._get_global_sandbox(pilot)
  File "/home/mingtha/ve/ve.exec_model_exp/local/lib/python2.7/site-packages/radical/pilot/session.py", line 774, in _get_global_sandbox
    shell = rsup.PTYShell(js_url, self)
  File "/home/mingtha/ve/ve.exec_model_exp/local/lib/python2.7/site-packages/saga/utils/pty_shell.py", line 247, in __init__
    interactive=self.interactive)
  File "/home/mingtha/ve/ve.exec_model_exp/local/lib/python2.7/site-packages/saga/utils/pty_shell_factory.py", line 198, in initialize
    self._initialize_pty (info['pty'], info)
  File "/home/mingtha/ve/ve.exec_model_exp/local/lib/python2.7/site-packages/saga/utils/pty_shell_factory.py", line 413, in _initialize_pty
    raise ptye.translate_exception (e)
PermissionDenied: read from process failed '[Errno 5] Input/output error' : (Permission denied (gssapi-keyex,gssapi-with-mic).
) ((Permission denied (gssapi-keyex,gssapi-with-mic).
)) (/home/mingtha/ve/ve.exec_model_exp/local/lib/python2.7/site-packages/saga/utils/pty_exceptions.py +61 (translate_exception)  :  e = se.PermissionDenied (cmsg))
2017-04-16 19:04:44,991: umgr.scheduling.1.child: umgr.scheduling.1               : MainThread     : ERROR   : unit schedule preparation failed
Traceback (most recent call last):
  File "/home/mingtha/ve/ve.exec_model_exp/local/lib/python2.7/site-packages/radical/pilot/umgr/scheduler/round_robin.py", line 131, in _schedule_units
    unit['sandbox'] = self._session._get_unit_sandbox(unit, pilot)
  File "/home/mingtha/ve/ve.exec_model_exp/local/lib/python2.7/site-packages/radical/pilot/session.py", line 846, in _get_unit_sandbox
    pilot_sandbox = self._get_pilot_sandbox(pilot)
  File "/home/mingtha/ve/ve.exec_model_exp/local/lib/python2.7/site-packages/radical/pilot/session.py", line 831, in _get_pilot_sandbox
    session_sandbox = self._get_session_sandbox(pilot)
  File "/home/mingtha/ve/ve.exec_model_exp/local/lib/python2.7/site-packages/radical/pilot/session.py", line 809, in _get_session_sandbox
    global_sandbox  = self._get_global_sandbox(pilot)
  File "/home/mingtha/ve/ve.exec_model_exp/local/lib/python2.7/site-packages/radical/pilot/session.py", line 774, in _get_global_sandbox
    shell = rsup.PTYShell(js_url, self)
  File "/home/mingtha/ve/ve.exec_model_exp/local/lib/python2.7/site-packages/saga/utils/pty_shell.py", line 247, in __init__
    interactive=self.interactive)
  File "/home/mingtha/ve/ve.exec_model_exp/local/lib/python2.7/site-packages/saga/utils/pty_shell_factory.py", line 198, in initialize
    self._initialize_pty (info['pty'], info)
  File "/home/mingtha/ve/ve.exec_model_exp/local/lib/python2.7/site-packages/saga/utils/pty_shell_factory.py", line 413, in _initialize_pty
    raise ptye.translate_exception (e)
PermissionDenied: read from process failed '[Errno 5] Input/output error' : (Permission denied (gssapi-keyex,gssapi-with-mic).
) ((Permission denied (gssapi-keyex,gssapi-with-mic).
)) (/home/mingtha/ve/ve.exec_model_exp/local/lib/python2.7/site-packages/saga/utils/pty_exceptions.py +61 (translate_exception)  :  e = se.PermissionDenied (cmsg))
2017-04-16 19:04:46,306: umgr.scheduling.1.child: umgr.scheduling.1               : MainThread     : ERROR   : unit schedule preparation failed
Traceback (most recent call last):
  File "/home/mingtha/ve/ve.exec_model_exp/local/lib/python2.7/site-packages/radical/pilot/umgr/scheduler/round_robin.py", line 131, in _schedule_units
    unit['sandbox'] = self._session._get_unit_sandbox(unit, pilot)
  File "/home/mingtha/ve/ve.exec_model_exp/local/lib/python2.7/site-packages/radical/pilot/session.py", line 846, in _get_unit_sandbox
    pilot_sandbox = self._get_pilot_sandbox(pilot)
  File "/home/mingtha/ve/ve.exec_model_exp/local/lib/python2.7/site-packages/radical/pilot/session.py", line 831, in _get_pilot_sandbox
    session_sandbox = self._get_session_sandbox(pilot)
  File "/home/mingtha/ve/ve.exec_model_exp/local/lib/python2.7/site-packages/radical/pilot/session.py", line 809, in _get_session_sandbox
    global_sandbox  = self._get_global_sandbox(pilot)
  File "/home/mingtha/ve/ve.exec_model_exp/local/lib/python2.7/site-packages/radical/pilot/session.py", line 774, in _get_global_sandbox
    shell = rsup.PTYShell(js_url, self)
  File "/home/mingtha/ve/ve.exec_model_exp/local/lib/python2.7/site-packages/saga/utils/pty_shell.py", line 247, in __init__
    interactive=self.interactive)
  File "/home/mingtha/ve/ve.exec_model_exp/local/lib/python2.7/site-packages/saga/utils/pty_shell_factory.py", line 198, in initialize
    self._initialize_pty (info['pty'], info)
  File "/home/mingtha/ve/ve.exec_model_exp/local/lib/python2.7/site-packages/saga/utils/pty_shell_factory.py", line 413, in _initialize_pty
    raise ptye.translate_exception (e)
PermissionDenied: read from process failed '[Errno 5] Input/output error' : (Permission denied (gssapi-keyex,gssapi-with-mic).
) ((Permission denied (gssapi-keyex,gssapi-with-mic).
)) (/home/mingtha/ve/ve.exec_model_exp/local/lib/python2.7/site-packages/saga/utils/pty_exceptions.py +61 (translate_exception)  :  e = se.PermissionDenied (cmsg))
2017-04-16 19:55:25,208: umgr.scheduling.1.child: umgr.scheduling.1               : MainThread     : ERROR   : TERM : umgr.scheduling.1.child run intr
2017-04-16 19:55:25,209: umgr.scheduling.1.child: umgr.scheduling.1               : MainThread     : ERROR   : TERM : umgr.scheduling.1.child run final
