2017-04-13 18:28:11,038: rp.session.Ubuntu-1604-xenial-64-minimal.mingtha.017269.0000: MainProcess                     : MainThread     : ERROR   : pymongo error: {'nModified': 0, 'nUpserted': 0, 'nMatched': 0, 'writeErrors': [{u'index': 670, u'code': 12501, u'errmsg': u'quota exceeded', u'op': {'control': 'umgr', 'description': {'kernel': None, 'executable': 'module load python; source $HOME/bin/ve.synapse/bin/activate; aimes-skeleton-synapse.py serial flops 1 1715750072310 65536 65536 0 0 0', 'name': None, 'restartable': False, 'stdout': None, 'output_staging': [], 'pre_exec': None, 'mpi': False, 'environment': None, 'cleanup': False, 'arguments': None, 'stderr': None, 'cores': 1, 'post_exec': None, 'input_staging': []}, 'stdout': None, 'exit_code': None, 'states': ['NEW'], 'uid': 'unit.000670', 'name': None, '_id': 'unit.000670', 'umgr': 'umgr.0000', 'cmd': [], 'state': 'NEW', 'sandbox': None, 'stderr': None, 'pilot': None, 'type': 'unit'}}], 'upserted': [], 'writeConcernErrors': [], 'nRemoved': 0, 'nInserted': 670}
Traceback (most recent call last):
  File "/home/mingtha/ve/ve.exec_model_exp/local/lib/python2.7/site-packages/radical/pilot/db/database.py", line 363, in insert_units
    res = bulk.execute()
  File "/home/mingtha/ve/ve.exec_model_exp/local/lib/python2.7/site-packages/pymongo/bulk.py", line 587, in execute
    return self.__bulk.execute(write_concern)
  File "/home/mingtha/ve/ve.exec_model_exp/local/lib/python2.7/site-packages/pymongo/bulk.py", line 433, in execute
    return self.execute_command(generator, write_concern)
  File "/home/mingtha/ve/ve.exec_model_exp/local/lib/python2.7/site-packages/pymongo/bulk.py", line 300, in execute_command
    raise BulkWriteError(full_result)
BulkWriteError: batch op errors occurred
2017-04-13 18:28:40,621: rp.session.Ubuntu-1604-xenial-64-minimal.mingtha.017269.0000: MainProcess                     : rp.session.Ubuntu-1604-xenial-64-minimal.mingtha.017269.0000.ctrl.watcher: ERROR   : control.pubsub.bridge died - shutting down
